予想
5が出力される。
tryブロック内でエラーが発生し、catchブロックに移りbreakによりforループが終了するように思えるが、finallyブロックは必ず実行されるため再びforループが実行され、xにiの値が代入される。

結果
5が出力された